<?xml version="1.0"?>
<robot name="hermesArm">

 <!-- **************************** LINKS ***************************** -->
  <link name="base"> 
    <inertial>
      <origin xyz="0 0 0" /> 
      <mass value="1.0" />
      <inertia  ixx="1.0" ixy="0.0"  ixz="0.0"  iyy="1.0"  iyz="0.0"  izz="1.0" />
    </inertial>
    <visual>
      <origin xyz="0 0 0"/>
      <geometry>
        <mesh filename="package://hermes_arm_kdl/stl/BaseSchunk.stl" />
      </geometry>
      <material name="link">
        <color rgba="0.4706 0.5451 0.5647 1"/>
      </material>
    </visual>
    <collision>
      <origin rpy="0 0 0" xyz="0 0 0"/>
      <geometry>
        <mesh filename="package://hermes_arm_kdl/stl/BaseSchunkLow.stl" />
      </geometry>
    </collision>	
  </link>

  <link name="link1"> 
    <inertial>
      <origin xyz="0 0 0" /> 
      <mass value="1.0" />
      <inertia  ixx="1.0" ixy="0.0"  ixz="0.0"  iyy="1.0"  iyz="0.0"  izz="1.0" />
    </inertial>
    <visual>
      <origin xyz="0 0 0"/>
      <geometry>
        <mesh filename="package://hermes_arm_kdl/stl/SchunkLink1.stl" />
      </geometry>
      <material name="motor">
        <color rgba="0.3922 0.3922 0.2118 1"/>
      </material>
    </visual>
    <collision>
      <origin rpy="0 0 0" xyz="0 0 0"/>
      <geometry>
        <mesh filename="package://hermes_arm_kdl/stl/SchunkLink1Low.stl" />
      </geometry>
    </collision>	
  </link>


  <link name="link2"> 
    <inertial>
      <origin xyz="0 0 0" /> 
      <mass value="1.0" />
      <inertia  ixx="1.0" ixy="0.0"  ixz="0.0"  iyy="1.0"  iyz="0.0"  izz="1.0" />
    </inertial>
    <visual>
      <origin xyz="0 0 0"/>
      <geometry>
        <mesh filename="package://hermes_arm_kdl/stl/SchunkLink2.stl" />
      </geometry>
      <material name="link">
        <color rgba="0.4706 0.5451 0.5647 1"/>
      </material>
    </visual>
    <collision>
      <origin rpy="0 0 0" xyz="0 0 0"/>
      <geometry>
        <mesh filename="package://hermes_arm_kdl/stl/SchunkLink2Low.stl" />
      </geometry>
    </collision>	
  </link>

  <link name="link3"> 
    <inertial>
      <origin xyz="0 0 0" /> 
      <mass value="1.0" />
      <inertia  ixx="1.0" ixy="0.0"  ixz="0.0"  iyy="1.0"  iyz="0.0"  izz="1.0" />
    </inertial>
    <visual>
      <origin xyz="0 0 0"/>
      <geometry>
        <mesh filename="package://hermes_arm_kdl/stl/SchunkLink3.stl" />
      </geometry>
      <material name="motor">
        <color rgba="0.3922 0.3922 0.2118 1"/>
      </material>
    </visual>
    <collision>
      <origin rpy="0 0 0" xyz="0 0 0"/>
      <geometry>
        <mesh filename="package://hermes_arm_kdl/stl/SchunkLink3Low.stl" />
      </geometry>
    </collision>	
  </link>

  <link name="link4"> 
    <inertial>
      <origin xyz="0 0 0" /> 
      <mass value="1.0" />
      <inertia  ixx="1.0" ixy="0.0"  ixz="0.0"  iyy="1.0"  iyz="0.0"  izz="1.0" />
    </inertial>
    <visual>
      <origin xyz="0 0 0"/>
      <geometry>
        <mesh filename="package://hermes_arm_kdl/stl/SchunkLink4.stl" />
      </geometry>
      <material name="link">
        <color rgba="0.4706 0.5451 0.5647 1"/>
      </material>
    </visual>
    <collision>
      <origin rpy="0 0 0" xyz="0 0 0"/>
      <geometry>
        <mesh filename="package://hermes_arm_kdl/stl/SchunkLink4Low.stl" />
      </geometry>
    </collision>	
  </link>

  <link name="link5"> 
    <inertial>
      <origin xyz="0 0 0" /> 
      <mass value="1.0" />
      <inertia  ixx="1.0" ixy="0.0"  ixz="0.0"  iyy="1.0"  iyz="0.0"  izz="1.0" />
    </inertial>
    <visual>
      <origin xyz="0 0 0"/>
      <geometry>
        <mesh filename="package://hermes_arm_kdl/stl/SchunkLink5.stl" />
      </geometry>
      <material name="motor">
        <color rgba="0.3922 0.3922 0.2118 1"/>
      </material>
    </visual>
    <collision>
      <origin rpy="0 0 0" xyz="0 0 0"/>
      <geometry>
        <mesh filename="package://hermes_arm_kdl/stl/SchunkLink5Low.stl" />
      </geometry>
    </collision>	
  </link>


  <link name="link6"> 
    <inertial>
      <origin xyz="0 0 0" /> 
      <mass value="1.0" />
      <inertia  ixx="1.0" ixy="0.0"  ixz="0.0"  iyy="1.0"  iyz="0.0"  izz="1.0" />
    </inertial>
    <visual>
      <origin xyz="0 0 0"/>
      <geometry>
        <mesh filename="package://hermes_arm_kdl/stl/SchunkLink6.stl" />
      </geometry>
      <material name="link">
        <color rgba="0.4706 0.5451 0.5647 1"/>
      </material>
    </visual>
    <collision>
      <origin rpy="0 0 0" xyz="0 0 0"/>
      <geometry>
        <mesh filename="package://hermes_arm_kdl/stl/SchunkLink6Low.stl" />
      </geometry>
    </collision>	
  </link>

  
 
  <link name="link7"> 
    <inertial>
      <origin xyz="0 0 0" /> 
      <mass value="1.0" />
      <inertia  ixx="1.0" ixy="0.0"  ixz="0.0"  iyy="1.0"  iyz="0.0"  izz="1.0" />
    </inertial>
    <visual>
      <origin xyz="0 0 0"/>
      <geometry>
        <mesh filename="package://hermes_arm_kdl/stl/SchunkLink7.stl" />
      </geometry>
      <material name="motor">
        <color rgba="0.3922 0.3922 0.2118 1"/>
      </material>
    </visual>
    <collision>
      <origin rpy="0 0 0" xyz="0 0 0"/>
      <geometry>
        <mesh filename="package://hermes_arm_kdl/stl/SchunkLink7Low.stl" />
      </geometry>
    </collision>	
  </link>



 <!-- **************************** JOINTS ***************************** -->
  <joint name="joint1" type="revolute">
    <parent link="base"/>
    <child link="link1"/>
    <origin xyz="0 0 -0.3060" rpy="1.5707963267949 0 0" />
    <limit effort="100" velocity="100" lower="-3.14" upper="3.14" />
    <axis xyz="0 1 0" />
  </joint>

  <joint name="joint2" type="revolute">
    <parent link="link1"/>
    <child link="link2"/>
    <origin xyz="0 0 0" rpy="-1.5707963267949 0 0" />
    <axis xyz="0 -1 0" />
    <limit effort="100" velocity="100" lower="-1.83" upper="1.83" />
  </joint>

  <joint name="joint3" type="revolute">
    <parent link="link2"/>
    <child link="link3"/>
    <origin xyz="0 0 -0.391" rpy="1.5707963267949 0 0" />
    <axis xyz="0 1 0" />
    <limit effort="100" velocity="100" lower="-3.14" upper="3.14" />
   </joint>

  <joint name="joint4" type="revolute">
    <parent link="link3"/>
    <child link="link4"/>
    <origin xyz="0 0 0" rpy="-1.5707963267949 0 0" />
    <axis xyz="0 -1 0" />
    <limit effort="100" velocity="100" lower="-1.83" upper="1.83" />
  </joint>

  <joint name="joint5" type="revolute">
    <parent link="link4"/>
    <child link="link5"/>
    <origin xyz="0 0 -0.2975" rpy="1.5707963267949 0 0" />
    <axis xyz="0 1 0" /> 
    <limit effort="100" velocity="100" lower="-3.14" upper="3.14" />
  </joint>

  <joint name="joint6" type="revolute">
    <parent link="link5"/>
    <child link="link6"/>
    <origin xyz="0 0 0" rpy="-1.5707963267949 0 0" />
    <axis xyz="0 -1 0" /> 
    <limit effort="100" velocity="100" lower="-1.83" upper="1.83" />
  </joint>

  <joint name="joint7" type="revolute">
    <parent link="link6"/>
    <child link="link7"/>
    <origin xyz="0 0 -0.3045" rpy="3.1416 0 0" />
    <axis xyz="0 0 -1" />
    <limit effort="100" velocity="100" lower="-3.14" upper="3.14" />
  </joint>

</robot>


